Workbook

Sheet Dashboard
B1: [Project Name] — Project Tracking Dashboard
B2: Auto-summary from all tracking sheets · Update data in individual sheets
B4: Total Deliverables | C4: Done / Closed | D4: In Progress | E4: Not Started | F4: Open Issues | G4: Open Defects
B5: =COUNTA(Scope!B5:B200) | C5: =COUNTIF(Scope!G5:G200,"Done")+COUNTIF(Scope!G5:G200,"Completed") | D5: =COUNTIF(Scope!G5:G200,"In Progress") | E5: =COUNTIF(Scope!G5:G200,"Not Started") | F5: =COUNTIFS(Issues!K5:K200,"Open",Issues!C5:C200,"<>") | G5: =COUNTIFS(Defects!$N$5:$N$1000,"Open",Defects!$C$5:$C$1000,"<>")+COUNTIFS(Defects!$N$5:$N$1000,"Pending",Defects!$C$5:$C$1000,"<>")
B7: Open Issues | C7: Open Defects | D7: Unanswered Q&As | E7: High/Critical Risks
B8: =COUNTIFS(Issues!K5:K200,"Open",Issues!C5:C200,"<>") | C8: =COUNTIFS(Defects!$N$5:$N$1000,"Open",Defects!$C$5:$C$1000,"<>")+COUNTIFS(Defects!$N$5:$N$1000,"Pending",Defects!$C$5:$C$1000,"<>") | D8: =COUNTIFS('Q&A'!K5:K200,"Open",'Q&A'!C5:C200,"<>") | E8: =COUNTIF(Risks!$F$6:$F$1000,">=4")
B11: Scope Milestone Status
B12: Stage | C12: Key Deliverable | D12: Deadline | E12: In Charge | F12: Status
B13: Stage 1 | C13: Report 1 (Project Introduction) | D13: Week 1 | F13: =IF(COUNTA(Scope!B6)=0,"",IF(COUNTIF(Scope!G6,"Done")=COUNTA(Scope!B6),"Done",IF(COUNTIF(Scope!G6,"Not Started")=COUNTA(Scope!B6),"Not Started","In Progress")))
B14: Stage 2 | C14: SRS v0.9 + Project Management Plan | D14: Week 3 | F14: =IF(COUNTA(Scope!B8:B10)=0,"",IF(COUNTIF(Scope!G8:G10,"Done")=COUNTA(Scope!B8:B10),"Done",IF(COUNTIF(Scope!G8:G10,"Not Started")=COUNTA(Scope!B8:B10),"Not Started","In Progress")))
B15: Stage 3 | C15: SDS v1.0 + Test Planning | D15: Week 5 | F15: =IF(COUNTA(Scope!B12:B15)=0,"",IF(COUNTIF(Scope!G12:G15,"Done")=COUNTA(Scope!B12:B15),"Done",IF(COUNTIF(Scope!G12:G15,"Not Started")=COUNTA(Scope!B12:B15),"Not Started","In Progress")))
B16: Stage 4 | C16: Implementation Iterations 1–3 | D16: Week 11 | F16: =IF(COUNTA(Scope!B17:B36)=0,"",IF(COUNTIF(Scope!G17:G36,"Done")=COUNTA(Scope!B17:B36),"Done",IF(COUNTIF(Scope!G17:G36,"Not Started")=COUNTA(Scope!B17:B36),"Not Started","In Progress")))
B17: Stage 5 | C17: System Test Report + User Guides + UAT | D17: Week 13 | F17: =IF(COUNTA(Scope!B38:B41)=0,"",IF(COUNTIF(Scope!G38:G41,"Done")=COUNTA(Scope!B38:B41),"Done",IF(COUNTIF(Scope!G38:G41,"Not Started")=COUNTA(Scope!B38:B41),"Not Started","In Progress")))
B18: Stage 6 | C18: Final Report + Presentation | D18: Week 14 | F18: =IF(COUNTA(Scope!B43:B44)=0,"",IF(COUNTIF(Scope!G43:G44,"Done")=COUNTA(Scope!B43:B44),"Done",IF(COUNTIF(Scope!G43:G44,"Not Started")=COUNTA(Scope!B43:B44),"Not Started","In Progress")))
B20: WBS by Iteration
B21: Iteration | C21: Planned Functions | D21: Est. Effort (pts) | E21: Done | F21: In Process | G21: % Complete
B22: Iteration 1 | C22: =COUNTIF(WBS!$I$5:$I$1100,$B22) | D22: =SUMIF(WBS!$I$5:$I$1100,$B22,WBS!$H$5:$H$1100) | E22: =COUNTIFS(WBS!$I$5:$I$1100,$B22,WBS!$L$5:$L$1100,"Done") | F22: =COUNTIFS(WBS!$I$5:$I$1100,$B22,WBS!$L$5:$L$1100,"In Progress") | G22: =IFERROR(ROUND(E22/(C22-COUNTIFS(WBS!$I$5:$I$1100,$B22,WBS!$L$5:$L$1100,"Cancelled"))*100,1),"")
B23: Iteration 2 | C23: =COUNTIF(WBS!$I$5:$I$1100,$B23) | D23: =SUMIF(WBS!$I$5:$I$1100,$B23,WBS!$H$5:$H$1100) | E23: =COUNTIFS(WBS!$I$5:$I$1100,$B23,WBS!$L$5:$L$1100,"Done") | F23: =COUNTIFS(WBS!$I$5:$I$1100,$B23,WBS!$L$5:$L$1100,"In Progress") | G23: =IFERROR(ROUND(E23/(C23-COUNTIFS(WBS!$I$5:$I$1100,$B23,WBS!$L$5:$L$1100,"Cancelled"))*100,1),"")
B24: Iteration 3 | C24: =COUNTIF(WBS!$I$5:$I$1100,$B24) | D24: =SUMIF(WBS!$I$5:$I$1100,$B24,WBS!$H$5:$H$1100) | E24: =COUNTIFS(WBS!$I$5:$I$1100,$B24,WBS!$L$5:$L$1100,"Done") | F24: =COUNTIFS(WBS!$I$5:$I$1100,$B24,WBS!$L$5:$L$1100,"In Progress") | G24: =IFERROR(ROUND(E24/(C24-COUNTIFS(WBS!$I$5:$I$1100,$B24,WBS!$L$5:$L$1100,"Cancelled"))*100,1),"")
B27: Last updated: [DD/MM/YYYY] | Project: [Project Name] | PM: [Name]

Sheet Scope
A1: Scope — Project Deliverables & Milestones
A2: Track all deliverables by stage · Update Status and Actual Effort each week · % Complete auto-calculated
A4: # | B4: Work Package / Deliverable | C4: In Charge | D4: Est. Effort (pds) | E4: Deadline | F4: % Complete | G4: Status | H4: Actual Effort (pds) | I4: Dependency | J4: Approved By | K4: Notes
A5: Stage 1: Project Initiating (Week 1)
A6: 1.1 | B6: Report 1 — Project Introduction | E6: Week 1 | F6: =IFERROR(H6/D6*100,"") | G6: Done
A7: Stage 2: Project Planning & Initial Requirements (Weeks 2–3)
A8: 2.1 | B8: Report 3 — SRS v0.9 (Overall Requirements) | E8: Week 2 | F8: =IFERROR(H8/D8*100,"") | G8: Done
A9: 2.2 | B9: Vertical Prototypes (Code Demo) | E9: Week 3 | F9: =IFERROR(H9/D9*100,"") | G9: Done
A10: 2.3 | B10: Report 2 — Project Management Plan v1.0 | E10: Week 3 | F10: =IFERROR(H10/D10*100,"") | G10: Done
A11: Stage 3: Software Design (Weeks 4–5)
A12: 3.1 | B12: Vertical Prototypes (POC / Proof of Concepts) | E12: Week 4 | F12: =IFERROR(H12/D12*100,"") | G12: Done
A13: 3.2 | B13: Report 4 — SDS v1.0 (High Level Design) | E13: Week 4 | F13: =IFERROR(H13/D13*100,"") | G13: Done
A14: 3.3 | B14: Report 5 — Test Planning | E14: Week 5 | F14: =IFERROR(H14/D14*100,"") | G14: Done
A15: 3.4 | B15: Report 3 — SRS v1.0 (Detailed — Iteration 1) | E15: Week 5 | F15: =IFERROR(H15/D15*100,"") | G15: Done
A16: Stage 4a: Implementation — Iteration 1 (Weeks 6–7)
A17: 4.1.1 | B17: Report 4 — SDS v1.1 (Detailed Design) | E17: Week 6 | F17: =IFERROR(H17/D17*100,"") | G17: Done
A18: 4.1.2 | B18: Code Package & Unit Testing Report — Iteration 1 | E18: Week 6 | F18: =IFERROR(H18/D18*100,"") | G18: Done
A19: 4.1.3 | B19: Report 5 — Integration Test Cases — Iteration 1 | E19: Week 6 | F19: =IFERROR(H19/D19*100,"") | G19: Done
A20: 4.1.4 | B20: Report 5 — Integration Test Report — Iteration 1 | E20: Week 7 | F20: =IFERROR(H20/D20*100,"") | G20: Done
A21: 4.1.5 | B21: Report 3 — SRS v1.1 (Detailed — Iteration 2) | E21: Week 7 | F21: =IFERROR(H21/D21*100,"") | G21: Done
A22: 4.1.6 | B22: Software Package Version 1 | E22: Week 7 | F22: =IFERROR(H22/D22*100,"") | G22: Done
A23: Stage 4b: Implementation — Iteration 2 (Weeks 8–9)
A24: 4.2.1 | B24: Report 4 — SDS v1.2 | E24: Week 8 | F24: =IFERROR(H24/D24*100,"") | G24: Done
A25: 4.2.2 | B25: Code Package & Unit Testing Report — Iteration 2 | E25: Week 8 | F25: =IFERROR(H25/D25*100,"") | G25: Done
A26: 4.2.3 | B26: Report 5 — Integration Test Cases — Iteration 2 | E26: Week 8 | F26: =IFERROR(H26/D26*100,"") | G26: Done
A27: 4.2.4 | B27: Report 5 — Integration Test Report — Iteration 2 | E27: Week 9 | F27: =IFERROR(H27/D27*100,"") | G27: Done
A28: 4.2.5 | B28: Report 3 — SRS v1.2 (Detailed — Iteration 3) | E28: Week 9 | F28: =IFERROR(H28/D28*100,"") | G28: Done
A29: 4.2.6 | B29: Software Package Version 2 | E29: Week 9 | F29: =IFERROR(H29/D29*100,"") | G29: Done
A30: Stage 4c: Implementation — Iteration 3 (Weeks 10–11)
A31: 4.3.1 | B31: Report 4 — SDS v1.3 | E31: Week 10 | F31: =IFERROR(H31/D31*100,"") | G31: Done
A32: 4.3.2 | B32: Code Package & Unit Testing Report — Iteration 3 | E32: Week 10 | F32: =IFERROR(H32/D32*100,"") | G32: Done
A33: 4.3.3 | B33: Report 5 — Integration Test Cases — Iteration 3 | E33: Week 10 | F33: =IFERROR(H33/D33*100,"") | G33: Done
A34: 4.3.4 | B34: Report 5 — Integration Test Report — Iteration 3 | E34: Week 11 | F34: =IFERROR(H34/D34*100,"") | G34: Done
A35: 4.3.5 | B35: Report 5 — System Test Cases | E35: Week 11 | F35: =IFERROR(H35/D35*100,"") | G35: Done
A36: 4.3.6 | B36: Software Package Version 3 | E36: Week 11 | F36: =IFERROR(H36/D36*100,"") | G36: Done
A37: Stage 5: Verification & Validation (Weeks 12–13)
A38: 5.1 | B38: Report 5 — System Test Report | E38: Week 12 | F38: =IFERROR(H38/D38*100,"") | G38: Done
A39: 5.2 | B39: Report 6 — User Guides (Installation + User Manuals) | E39: Week 12 | F39: =IFERROR(H39/D39*100,"") | G39: Done
A40: 5.3 | B40: Acceptance Test and Support | E40: Week 13 | F40: =IFERROR(H40/D40*100,"") | G40: Done
A41: 5.4 | B41: Final Software Package (Docs + Source Codes) | E41: Week 13 | F41: =IFERROR(H41/D41*100,"") | G41: Done
...

Sheet WBS
B1: WBS — Work Breakdown Structure (Function / Screen Level)
B2: Complexity: Simple (≤7 fields / ≤3 tx) · Medium (≤15 / ≤7) · Complex (>15 / >7) · Effort: Simple=3 / Medium=5 / Complex=8 pts (default)
A4: # | B4: Function / Screen | C4: Type | D4: Feature Group | E4: Sub-Feature | F4: Description | G4: Complexity | H4: Est. Effort (pts) | I4: Planned Iteration | J4: In Charge | K4: Actual Effort (pts) | L4: Status | M4: Notes
A5: 1 | B5: Create AGV | C5: Screen | D5: FE-01: AGV Fleet Management | E5: AGV Profile | F5: Add a new AGV to the system database. | G5: Simple | H5: 3 | I5: Iteration 1 | J5: HungPV | L5: Done
A6: 2 | B6: Update AGV information | C6: Screen | D6: FE-01: AGV Fleet Management | E6: AGV Profile | F6: Modify existing AGV details (name, model, etc.). | G6: Simple | H6: 3 | I6: Iteration 1 | J6: HungPV | L6: Done
A7: 3 | B7: Delete AGV | C7: Screen | D7: FE-01: AGV Fleet Management | E7: AGV Profile | F7: Remove an AGV record from the system. | G7: Simple | H7: 3 | I7: Iteration 1 | J7: HungPV | L7: Done
A8: 4 | B8: View AGV list | C8: Screen | D8: FE-01: AGV Fleet Management | E8: AGV Profile | F8: Display a paginated table of all registered AGVs. | G8: Simple | H8: 3 | I8: Iteration 1 | J8: HungPV | L8: Done
A9: 5 | B9: View AGV details | C9: Screen | D9: FE-01: AGV Fleet Management | E9: AGV Profile | F9: Show specific properties and current status of an AGV. | G9: Simple | H9: 3 | I9: Iteration 1 | J9: HungPV | L9: Done
A10: 6 | B10: Configure critical battery threshold | C10: Screen | D10: FE-01: AGV Fleet Management | E10: AGV Configuration | F10: Set the critical battery percentage at or below which an AGV must go and charge. | G10: Simple | H10: 3 | I10: Iteration 1 | J10: HungPV | L10: Done
A11: 7 | B11: Configure sufficient battery threshold | C11: Screen | D11: FE-01: AGV Fleet Management | E11: AGV Configuration | F11: Set the battery percentage at or above which a charging AGV is sufficiently charged to rejoin dispatch. | G11: Simple | H11: 3 | I11: Iteration 1 | J11: HungPV | L11: Done
A12: 8 | B12: Enable AGV to accept requests | C12: Screen | D12: FE-01: AGV Fleet Management | E12: AGV Status Control | F12: Manually allow an AGV to receive dispatch commands. | G12: Simple | H12: 3 | I12: Iteration 1 | J12: HungPV | L12: Done
A13: 9 | B13: Disable AGV from accepting requests | C13: Screen | D13: FE-01: AGV Fleet Management | E13: AGV Status Control | F13: Manually stop an AGV from receiving new dispatch commands. | G13: Simple | H13: 3 | I13: Iteration 1 | J13: HungPV | L13: Done
A14: 10 | B14: Ignore AGV from the system | C14: Screen | D14: FE-01: AGV Fleet Management | E14: AGV Status Control | F14: Exclude an AGV from orchestration without deleting it. | G14: Simple | H14: 3 | I14: Iteration 1 | J14: HungPV | L14: Done
A15: 11 | B15: Restore ignored AGV | C15: Screen | D15: FE-01: AGV Fleet Management | E15: AGV Status Control | F15: Re-include an ignored AGV back into orchestration. | G15: Simple | H15: 3 | I15: Iteration 1 | J15: HungPV | L15: Done
A16: 12 | B16: Activate / Deactivate AGV | C16: Screen | D16: FE-01: AGV Fleet Management | E16: AGV Status Control | F16: Enable or disable an AGV's link to the fleet kernel so that only vehicles physically present and ready are tracked and controlled. | G16: Medium | H16: 5 | I16: Iteration 1 | J16: HungPV | L16: Done
... A133: 129 | B133: openTCS component replacement (Dispatcher / Router / Scheduler) | C133: Non-UI | D133: FE-08: Multi-Agent Traffic Coordination (FMS) | E133: Traffic Control | F133: Thay ba thành phần chuẩn của openTCS bằng bản của FMS thông qua Guice binding trong kernel: Dispatcher, Router và Scheduler cùng module precedence, để MAPF điều phối được cả đội xe trong khi vẫn giữ nguyên vòng đời transport order và giao diện REST mà WES đang gọi. | G133: Complex | H133: 14 | I133: Iteration 2 | J133: HungPV, DucNH | L133: Done
B134: Iteration Summary
B135: Iteration | C135: Planned Functions | D135: Est. Effort (pts) | E135: Done | F135: In Progress
B136: Iteration 1 | C136: =COUNTIF($I$5:$I$1100,$B136) | D136: =SUMIF($I$5:$I$1100,$B136,$H$5:$H$1100) | E136: =COUNTIFS($I$5:$I$1100,$B136,$L$5:$L$1100,"Done") | F136: =COUNTIFS($I$5:$I$1100,$B136,$L$5:$L$1100,"In Progress")
B137: Iteration 2 | C137: =COUNTIF($I$5:$I$1100,$B137) | D137: =SUMIF($I$5:$I$1100,$B137,$H$5:$H$1100) | E137: =COUNTIFS($I$5:$I$1100,$B137,$L$5:$L$1100,"Done") | F137: =COUNTIFS($I$5:$I$1100,$B137,$L$5:$L$1100,"In Progress")
B138: Iteration 3 | C138: =COUNTIF($I$5:$I$1100,$B138) | D138: =SUMIF($I$5:$I$1100,$B138,$H$5:$H$1100) | E138: =COUNTIFS($I$5:$I$1100,$B138,$L$5:$L$1100,"Done") | F138: =COUNTIFS($I$5:$I$1100,$B138,$L$5:$L$1100,"In Progress")
B139: Grand Total | C139: =SUM(C136:C138) | D139: =SUM(D136:D138) | E139: =SUM(E136:E138) | F139: =SUM(F136:F138)

Sheet Q&A
A1: Q&A — Project Questions & Answers Log
A2: Log ALL questions — technical, business, process · Track from Open → Answered → Closed · Never delete a row
A4: # | B4: Date | C4: Question | D4: Raised By | E4: Directed To | F4: Priority | G4: Due Date | H4: Answer / Resolution | I4: Answered By | J4: Answered Date | K4: Status | L4: Notes
A5: Q-001 | B5: 2024-01-08 | C5: [Describe the question clearly — what needs clarification?] | D5: KienNT | E5: [Assignee/Stakeholder] | F5: Medium | G5: 2024-01-15 | H5: [Answer provided here] | K5: Open
A6: Q-002 | F6: Medium | K6: Open
A7: Q-003 | F7: Medium | K7: Open
A8: Q-004 | F8: Medium | K8: Open
A9: Q-005 | F9: Medium | K9: Open
A10: Q-006 | F10: Medium | K10: Open
A11: Q-007 | F11: Medium | K11: Open
A12: Q-008 | F12: Medium | K12: Open
A13: Q-009 | F13: Medium | K13: Open
A14: Q-010 | F14: Medium | K14: Open
A15: Q-011 | F15: Medium | K15: Open
A16: Q-012 | F16: Medium | K16: Open
A17: Q-013 | F17: Medium | K17: Open
... A24: Q-020 | F24: Medium | K24: Open

Sheet TimeLogs
A1: TimeLogs — Project Timesheets
A2: Log time daily · Link every entry to a WBS Ref · Approved by PM · # Hours must be filled — leave no blank
A4: # | B4: Date | C4: Reporter | D4: WBS Ref | E4: Task Description | F4: Activity | G4: Type | H4: # Hours | I4: Product / Work Product | J4: Iteration | K4: Status | L4: Approved By | M4: Updated | N4: Notes
A5: TL-001 | B5: 2024-10-13 | D5: WBS-1 | E5: Set up project repository and CI pipeline | F5: Coding | G5: Newly-Created | H5: 2 | I5: Software Package | J5: Iteration 1 | K5: Submitted | M5: 2024-10-26
A6: TL-002 | D6: WBS-2 | E6: Implement user login API with JWT | F6: Coding | G6: Newly-Created | H6: 4 | I6: Software Package | J6: Iteration 1 | K6: Submitted
A7: TL-003 | K7: Submitted
A8: TL-004 | K8: Submitted
A9: TL-005 | K9: Submitted
A10: TL-006 | K10: Submitted
A11: TL-007 | K11: Submitted
A12: TL-008 | K12: Submitted
A13: TL-009 | K13: Submitted
A14: TL-010 | K14: Submitted
A15: TL-011 | K15: Submitted
A16: TL-012 | K16: Submitted
A17: TL-013 | K17: Submitted
A18: TL-014 | K18: Submitted
... A35: TL-031 | K35: Submitted
A39: Hours Summary
A40: Activity | B40: Total Hours
A41: Training | B41: =SUMIF(F5:F500,"Training",H5:H500)
A42: Analyzing | B42: =SUMIF(F5:F500,"Analyzing",H5:H500)
A43: Designing | B43: =SUMIF(F5:F500,"Designing",H5:H500)
A44: Coding | B44: =SUMIF(F5:F500,"Coding",H5:H500)
A45: Testing | B45: =SUMIF(F5:F500,"Testing",H5:H500)
A46: Reviewing | B46: =SUMIF(F5:F500,"Reviewing",H5:H500)
A47: Deploying | B47: =SUMIF(F5:F500,"Deploying",H5:H500)
A48: Meeting | B48: =SUMIF(F5:F500,"Meeting",H5:H500)
A49: Grand Total | B49: =SUM(H5:H500)

Sheet Defects
A1: Defects — Bug & Defect Tracking Log
A2: Log ALL defects found in any review or test · Severity: Critical / High / Medium / Low · Status: Pending → Open → Fixed → Closed
A4: # | B4: Date Found | C4: Defect Description | D4: Steps to Reproduce | E4: Expected Result | F4: Actual Result | G4: Severity | H4: Priority | I4: Activity | J4: Product | K4: Product Details | L4: Assigned By | M4: Assigned To | N4: Status | O4: Fixed Date | P4: Fixed In Version | Q4: Updated | R4: Notes
A5: D-001 | B5: 2026-07-20 | C5: Deleting an operational location does not check for cargo still referencing it | D5: 1. Create cargo whose destination is zone Z. 2. Before delivery, delete zone Z. | E5: Deletion is refused while active cargo references the zone | F5: Zone is soft-deleted and its locations are stripped from the openTCS plant model; the in-flight task breaks | G5: High | H5: High | I5: Review | J5: Software Package | L5: KienNT | M5: HungPV | N5: Open | Q5: 2024-10-26 | R5: ZoneService.remove() has no guard. Fix together with BR-12.
A6: D-002 | B6: 2026-07-20 | C6: Deactivating an AGV removes it from the kernel entirely instead of leaving it in place as a static obstacle. AgvsService.disconnect() sets the vehicle's integration level to TO_BE_IGNORED and then disables the communication adapter. | D6: 1. Park an AGV on a point that lies on a route other vehicles use. 2. Deactivate that AGV from the AGV list screen. 3. Create a transport request whose shortest route passes through that point. | E6: The AGV is no longer dispatched, but the kernel still treats the point it occupies as blocked, so other vehicles route around it. | F6: The kernel ignores the vehicle completely; other vehicles are routed straight through the occupied point. | G6: High | H6: High | I6: Review | J6: Software Package | K6: wes/src/agvs/agvs.service.ts:206 | L6: HungPV | N6: Fixed | O6: 2026-07-25 | R6: Fixed 2026-07-25 (commit e6e79ca). ignore() now sets TO_BE_RESPECTED (agvs.service.ts:187), so an ignored AGV is withheld from dispatch while its position is still respected by fleet routing, which is what BR-06 requires. disconnect() keeps TO_BE_IGNORED - that path removes the vehicle from the fleet altogether and is a different operation.
A7: D-003 | B7: 2026-07-20 | C7: The zones and cargo controllers are guarded by authentication only, not by role, so any authenticated user including an Operator can call every mutation on those modules - including delete. | D7: 1. Log in as a user holding the operator role. 2. Send DELETE /zones/{id} using that user's token. | E7: The request is rejected with 403 Forbidden, as it is on the AGV and dispatch-policy controllers. | F7: The request succeeds and the record is deleted. | G7: Critical | H7: High | I7: Review | J7: Software Package | K7: wes/src/zones/zone.controller.ts:16; wes/src/cargo/cargo.controller.ts:19 | L7: HungPV | N7: Open | R7: Both declare @UseGuards(JwtAuthGuard) only. For comparison agvs.controller.ts:21 and dispatch-policy.controller.ts:22 declare @UseGuards(JwtAuthGuard, RolesGuard) with @Roles('admin'). These are the only two controllers with no role check.
A8: D-004 | B8: 2026-07-20 | C8: The isIgnored flag on an AGV can never be changed. It is declared on the entity and read in three places, but no DTO, endpoint or service method ever writes it, so it stays false for the lifetime of the record. | D8: 1. Open an AGV detail screen. 2. Attempt to exclude the AGV from orchestration (WBS #10). 3. Read the is_ignored column for that AGV. | E8: The flag is set to true and the assignment engine stops offering work to that AGV. | F8: No request path writes the flag; it stays false and the AGV keeps receiving work. | G8: High | H8: High | I8: Review | J8: Software Package | K8: wes/src/agvs/entities/agv.entity.ts:33 | L8: HungPV | N8: Closed | O8: 2026-07-28 | Q8: 2026-07-28 | R8: Closed 2026-07-28. The write path now exists: POST /agvs/{id}/ignore and /restore (agvs.controller.ts:71-81) write is_ignored and push the kernel integration level (TO_BE_RESPECTED / TO_BE_UTILIZED) in agvs.service.ts:181-207; /enable and /disable do the same for is_dispatch_enabled. Eligibility is enforced in dispatch.policy.ts:19-20, parking.policy.ts:51-52 and charge.policy.ts:25-26, each covered by unit tests, and all four actions are exposed on the operation-map vehicle panel (wes-client/src/features/map/VehicleControlPanel.tsx:308-351, mounted from MapCanvas.tsx:352). Verified by code inspection on 2026-07-28; no live UI retest was run. WBS #8-#11 moved to Done accordingly. Original finding: the flag was declared and read in three places but never written by any DTO, endpoint or service method.
A9: D-005 | B9: 2026-07-20 | C9: The k-robustness safety buffer is honoured on only one of the two planning paths. The windowed PIBT fallback enforces it; the LaCAM search does not, and a plan violating the requested buffer is still returned and executed. | D9: 1. Set kRobust to 1. 2. Run a scenario in which the LaCAM search, not the windowed fallback, produces the plan. 3. Read the kernel log. | E9: A plan violating the requested buffer is rejected and the solver falls back to one that satisfies it. | F9: The plan is returned and used; the violation is only reported as an error in the log. | G9: Medium | H9: Medium | I9: Review | J9: Software Package | K9: LacamSolver.java:399; PibtEngine.java:311,329 | L9: HungPV | N9: Open | R9: Enforcement exists at PibtEngine.java:311 and 329. The verifier isKRobust is called from finish() at line 399, which logs but does not reject; the message at line 401 states the limitation. Default kRobust is 0, so the gap stays latent until a non-zero value is configured.
A10: D-006 | B10: 2026-07-20 | C10: The plant-model parser reads <property> children of <vehicle> only. Properties declared on point, path, location and block elements are silently discarded, so a map uploaded through WES reaches the kernel with those settings missing. | D10: 1. Add a property such as tcs:parkingPositionPriority to a point in the map XML. 2. Upload the map through WES. 3. Read that point back from the kernel. | E10: The property is present on the point in the kernel's plant model. | F10: The property is absent and no warning is emitted. | G10: Medium | H10: Medium | I10: Review | J10: Software Package | K10: wes/src/opentcs/map-loader/opentcs-xml.parser.ts:259 | L10: HungPV | N10: Open | R10: Only VehicleDto declares a properties field (line 46); PointDto, PathDto, LocationDto and BlockDto do not. Same defect class as the vehicle-property loss recorded in Issue I-005, which remains open for this reason.
A11: D-007 | B11: 2026-07-25 | C11: On the operation map the cargo box stays drawn at its pick-up point after the AGV has already picked it up and driven away. Vehicles are drawn from a live SSE stream while cargo state is polled every 5 seconds, so the two layers are never in step. | D11: 1. Open Bản đồ → Xem vận hành with at least one AGV in service. 2. Create a cargo and wait for it to be dispatched. 3. Watch the AGV arrive at the pick-up point, complete the pick-up and drive away. | E11: The cargo box moves onto the AGV in the same moment the AGV starts driving away from the pick-up point. | F11: The AGV drives away with an empty back; the cargo box jumps onto it up to 5 seconds later, and does not move at all while the browser window is unfocused. | G11: Medium | H11: High | I11: System Test | J11: Software Package | K11: wes-client/src/features/map/queries.ts:38; wes-client/src/features/map/useMapShapes.tsx:573 | L11: HungPV | N11: Open | R11: Only the state flip is late, not the drawing - once visual.state is ON_AGV the box follows the vehicle live. The backend publishes ON_AGV as soon as the task reaches DELIVERING, which TransportTaskSaga sets in the same handler that creates the approach order, i.e. at the moment the vehicle starts moving. The delay is entirely client-side: useCanvasCargosQuery polls on a 5s interval and react-query's refetchIntervalInBackground defaults to false, so the poll stops while the window is unfocused. Fix: push cargo/task changes over the existing SSE channel, or invalidate the cargo query when a vehicle frame reports a procState change.
A12: D-008 | B12: 2026-07-25 | C12: When the vehicle SSE stream drops, the operation map silently freezes: vehicles stay drawn at their last known position and only a full page reload brings the map back to life. | D12: 1. Open Bản đồ → Xem vận hành while AGVs are moving. 2. Break the stream - restart the WES backend, or make /api/maps/kernel/sse return an error through the dev proxy. 3. Keep watching the canvas without reloading. | E12: The client reconnects on its own and vehicles keep moving; while it is disconnected the operator is told the live view is stale. | F12: Vehicles freeze at their last position with no warning of any kind, and only F5 restores live movement. | G12: High | H12: High | I12: System Test | J12: Software Package | K12: wes-client/src/features/map/useVehicleTracking.ts:23; wes-client/src/lib/query.ts:3 | L12: HungPV | N12: Open | R12: The EventSource is created once with an onmessage handler and no onerror handler, so a failed stream is neither retried by the app nor surfaced to the operator; the browser's own retry covers a clean transport drop, not an HTTP error response such as the one a backend restart produces through the dev proxy. Nothing else refreshes the fleet: the kernel-vehicles query has no refetchInterval and the global query defaults set refetchOnWindowFocus to false with staleTime 10s, so once the stream is gone the snapshot is never fetched again. Fix: handle onerror with a backoff reconnect, refetch the vehicle snapshot on every (re)connect, and show a disconnected banner.
A13: D-009 | B13: 2026-07-25 | C13: Every vehicle frame arriving on the SSE stream re-renders the whole operation map and writes a console.log line. One vehicle changing position rebuilds the Konva shapes of every vehicle and every cargo, so the canvas gets heavier as the fleet grows. | D13: 1. Open Bản đồ → Xem vận hành with the full fleet in service. 2. Open the browser devtools console. 3. Pan, zoom and select vehicles while they are moving. | E13: A frame for one vehicle updates that vehicle only, and the client logs nothing to the console. | F13: Each frame replaces the whole vehicle array, so all vehicle and cargo shapes are recomputed, and each frame prints a formatted console line - the kernel heartbeat alone pushes one frame per vehicle every 5 seconds on top of the live movement frames. | G13: Medium | H13: Medium | I13: System Test | J13: Software Package | K13: wes-client/src/features/map/useVehicleTracking.ts:41; wes-client/src/features/map/MapCanvasTab.tsx:51 | L13: HungPV | N13: Fixed | O13: 2026-08-04 | R13: Fixed 2026-08-04 (wes-client commit e9f2306). Each vehicle is now drawn by its own memoised component (VehicleShapes.tsx:175) and motion is interpolated per frame in useVehicleMotion, so a snapshot that changes one vehicle no longer re-renders every shape on the map.
A14: D-010 | B14: 2026-07-28 | C14: Park-point claims were released whenever the vehicle's transport order changed, instead of when the claimed park order itself ended. PointReservationStore.reconcile() dropped a claim as soon as vehicle.transportOrder was non-null, so a cargo order, a charge order or a manually issued Move order all cleared a claim whose park order was still queued in the kernel. WES then issued duplicate park orders and sent a second vehicle to a point already promised to another. | D14: 1. Run a cargo batch with the full fleet. 2. Query the kernel's transport orders filtered by one vehicle. 3. Compare the number of PARK-* orders created against the number of deliveries. | E14: At most one live park order per vehicle, and a park point held for that vehicle until it arrives or its order reaches a final state. | F14: Four park orders for the same vehicle within 22 seconds and 214 park orders for 80 deliveries. Vehicles were ordered onto points another vehicle already occupied; because openTCS applies no timeout to a transport order, such a vehicle waits at the adjacent point indefinitely and an operator has to withdraw the order by hand. | G14: High | H14: High | I14: System Test | J14: Software Package | K14: wes/src/cargo/point-reservation.store.ts:36 (deleted) - replaced by wes/src/cargo/park-claim.store.ts | L14: HungPV | N14: Fixed | O14: 2026-07-29 | R14: Fixed 2026-07-29. The release rule now compares the exact order name and, when the vehicle snapshot cannot settle it, asks the kernel for that order's state. Park orders fell from 214 to 4 on a comparable run. Evidence: wes/report/park-claims-findings.md; rules: ARCHITECTURE.md 6.4.
A15: D-011 | B15: 2026-07-28 | C15: Park-point claims lived only in process memory, so every backend restart dropped them and a point already promised to one vehicle was handed to a second. | D15: 1. Let an idle vehicle be issued a park order to point P. 2. While that order is still queued in the kernel and the vehicle has not yet reached P, restart the backend - under `pnpm start:dev` any file save does this. 3. Observe which park point the next idle vehicle is sent to. | E15: P stays claimed for the first vehicle until it arrives or its order reaches a final state, so no second vehicle is sent there. | F15: After the restart WES holds no record of the claim on P. P is treated as free and a second vehicle is ordered to park there. | G15: Medium | H15: Medium | I15: System Test | J15: Software Package | K15: wes/src/cargo/park-claim.store.ts:80 | L15: HungPV | N15: Fixed | O15: 2026-07-29 | R15: Fixed 2026-07-29 by rebuilding the ledger from GET /v1/transportOrders on application bootstrap. Until that query succeeds no engine may create a park order, because reading an empty ledger as 'nothing is claimed' is exactly how duplicate claims arise.
A16: D-012 | B16: 2026-08-04 | C16: The approach point for the delivery leg is chosen before the drop-off slot is known, so a vehicle can be sent to a gate from which its own slot cannot be reached. | D16: 1. Run a cargo batch into a drop-off zone whose columns each have a single entry gate. 2. Watch a vehicle finish its pick-up leg and receive its approach order. 3. Compare the gate it was sent to with the column of the slot the delivery slot engine assigns on arrival. | E16: The vehicle is sent to the gate of the column that contains its drop-off slot. | F16: V-0014 was sent to gate 3065 (column B) at 14:17:31. The slot computed when it arrived at 14:17:39 was 3130, which sits in column A behind gate 3073. The vehicle had to leave the zone and drive a full loop before it could enter, finishing at 14:19:00 instead of 14:18:05. The deepest slot stayed empty while two shallower ones were already filled. | G16: High | H16: High | I16: System Test | J16: Software Package | K16: wes/src/cargo/transport-task.saga.ts:119 (approach point issued) against :284 (slot computed) | L16: HungPV | N16: Open | R16: The gate is picked by ApproachPointService.pickFor, which selects the feeder nearest to the vehicle. Distance from the vehicle to a gate and membership of a slot in a column are unrelated quantities, so a correct gate is a coincidence rather than a decision.
A17: D-013 | B17: 2026-08-04 | C17: The approach point is selected one vehicle at a time, so two vehicles can be committed to the same gate, and therefore the same column, at once. | D17: 1. Run a cargo batch with several vehicles delivering into the same zone. 2. Record the approach point issued to each vehicle. 3. Look for two live approach orders naming the same gate. | E17: Two vehicles are never committed to the same gate at the same time. | F17: V-0006 was sent to gate 3065 while V-0014 was still standing on it. Traffic coordination pushed V-0006 off the point and it re-entered three times, losing 11 seconds. | G17: Medium | H17: Medium | I17: System Test | J17: Software Package | K17: wes/src/cargo/approach-point.service.ts:14 - pickFor takes a single vehicleName | L17: HungPV | N17: Open | R17: Independent of D-012: computing the slot before choosing the gate does not stop two vehicles choosing the same gate, because pickFor evaluates one vehicle at a time with no knowledge of the gates the others are already heading to.
A18: D-014 | B18: 2026-08-05 | C18: The AllocatorTask SEVERE flood ("Not allocating resources that are not next claimed resources") stalls the kernel's REST API: LOG.error runs inside synchronized(globalSyncObject) and the JUL FileHandler writes to disk synchronously, so every one of those log lines holds the kernel's global lock while doing file I/O. | D18: 1. Run the full-cargo batch of 80 tasks (scripts/scenarios/fullpick-80-4zone.json). 2. While the batch runs, sample GET /v1/vehicles at about 9 Hz and record p50/p99/max latency. 3. Count SEVERE lines in the kernel log over the same time window. | E18: /v1/vehicles latency stays near its p50 and does not depend on how many lines the kernel is logging. | F18: p50 = 2 ms but p99 = 746 ms and max = 1003 ms (batch 10:02:04-10:10:02, 477.2 s). The same window holds 8,214 SEVERE lines = 8.44 per dispatch cycle, 67.6 percent of the log bytes, with the log ring rotating every 107-165 s. Suspected downstream effect: the live map receives bunched-then-stale frames; 111 A-B-A position oscillations were measured, every one completing its round trip in under 400 ms. | G18: High | H18: Medium | I18: System Test | J18: Software Package | K18: openTCS kernel 7.3.0 - AllocatorTask.tryAllocate() and DefaultScheduler; WES REST /v1/vehicles; live map | L18: HungPV | N18: Open | Q18: 2026-08-05 | R18: NOT FIXED. The defect is in stock openTCS 7.3.0, consumed as a binary Maven dependency, so it cannot be patched directly. The FMSScheduler.claim() override cut SEVERE from 22,204 to 4,680, but this batch rose again to 8,214 and that regression is unexplained. Note that resyncClaimTo() never logged once, i.e. isNextInClaim() passed on every synchronous allocate(), so the claim divergence appears AFTER enqueue on the kernelExecutor; only shadowing AllocatorTask can reach it. The causal link between the REST stalling and the map flicker is so far only a correlation in the numbers, NOT proven.
A19: D-015 | G19: Medium | H19: Medium | N19: Pending
A20: D-016 | G20: Medium | H20: Medium | N20: Pending
A21: D-017 | G21: Medium | H21: Medium | N21: Pending
A22: D-018 | G22: Medium | H22: Medium | N22: Pending
A23: D-019 | G23: Medium | H23: Medium | N23: Pending
A24: D-020 | G24: Medium | H24: Medium | N24: Pending
A25: D-021 | G25: Medium | H25: Medium | N25: Pending
A26: D-022 | G26: Medium | H26: Medium | N26: Pending
A27: D-023 | G27: Medium | H27: Medium | N27: Pending
A28: D-024 | G28: Medium | H28: Medium | N28: Pending
A29: D-025 | G29: Medium | H29: Medium | N29: Pending
A30: D-026 | G30: Medium | H30: Medium | N30: Pending
... A34: D-030 | G34: Medium | H34: Medium | N34: Pending

Sheet Issues
A1: Issues — Project Issues & Risk Events Log
A2: Issues = problems that have already occurred · Risks = problems that might occur (see Risks sheet) · Category: Technical / Process / Resource / Scope / External
A4: # | B4: Date | C4: Issue Description | D4: Category | E4: Priority | F4: Impact (Scope / Effort / Timeline) | G4: Raised By | H4: Owner | I4: Due Date | J4: Resolution | K4: Status | L4: Closed Date | M4: Notes
A5: I-001 | B5: 2026-07-11 | C5: Fleet of 20 vehicles deadlocked. The planner validates a plan assuming every vehicle steps at the same time; in execution each vehicle moves at its own pace. A plan in which four vehicles each advance into the cell the next one is leaving passes that lockstep check, but at run time every vehicle waits for the one ahead to physically clear its cell. With no empty cell anywhere in the ring, none can move first and all four wait forever. | D5: Technical | E5: Critical | F5: Roughly one run in six froze the entire fleet; no scenario above 20 vehicles could be demonstrated. | G5: HungPV | H5: HungPV | J5: Added cycle detection over the action-dependency graph (hasAdgCycle) and gated plan acceptance on it (isExecutableAsync), applied both to the incumbent plan and to the return path. Enabled by default via fms.mapf.adgAcyclic. The 20-vehicle scenario then passed 6 of 6 runs. | K5: Closed | L5: 2026-07-13 | M5: The bounded node budget from I-002 was part of this fix, not a separate optimisation - without it the deadlock could not be reproduced reliably enough to diagnose.
A6: I-002 | B6: 2026-07-13 | C6: The same planning problem produced four different plans across eight runs. The solver keeps improving its plan until a wall-clock deadline and returns the best found so far, so machine load decides how many iterations fit and therefore which plan comes back. | D6: Technical | E6: High | F6: Regression results could not be trusted: a red test often passed on rerun, so no solver change could be judged by a before/after run. | G6: HungPV | H6: HungPV | J6: Replaced the wall-clock cut-off with a fixed search-node budget of 200,000 nodes, making the solver deterministic for a given input. The 20-vehicle deadlock then reproduced on every run and could be traced to its root cause. | K6: Closed | L6: 2026-07-13 | M6: Suite runtime also dropped from 1m21s to 18s.
A7: I-003 | B7: 2026-07-14 | C7: Vehicles collided beyond the planning window. The planner only checks vehicles against each other inside a limited look-ahead window; past that window it appended each vehicle's remaining route to its goal with no mutual collision check at all. | D7: Technical | E7: Critical | F7: Every tail measured collided - 448 of 448 - and a fleet of 25 vehicles could not complete a run. | G7: HungPV | H7: HungPV | J7: Three changes were required together: a fallback gate on the executable flag, restricting certification to the planning window (certifyWindowOnly), and parking idle vehicles off the running lanes. The full suite then passed 5 of 5. | K7: Closed | L7: 2026-07-14 | M7: certifyWindowOnly on its own made matters worse - 20 vehicles failed 3 of 3 runs until the fallback gate was also in place. A patch must not be judged while the change it depends on is missing.
A8: I-004 | B8: 2026-07-11 | C8: A frozen fleet never recovered on its own. Dispatching was triggered only by events such as an order arriving or a vehicle finishing a move. Once the whole fleet was stuck no event could fire, so dispatch was never called and nothing re-planned. | D8: Technical | E8: High | F8: A live log showed zero dispatch() calls across ten minutes; any deadlock was permanent rather than transient and needed a manual restart. | G8: HungPV | H8: HungPV | J8: Added a one-second timer in FMSDispatcher that calls dispatch() whenever the planner is overdue, so recovery no longer depends on an event that will never arrive. | K8: Closed | L8: 2026-07-11 | M8: The timer task must catch Throwable - scheduleAtFixedRate stops forever, silently, if the task throws.
A9: I-005 | B9: 2026-07-16 | C9: Map uploads made through WES silently lost vehicle properties. The XML parser did not read <property> children of <vehicle>, so preferredAdapterClass and every vda5050 setting was dropped before the model reached the kernel. The kernel then attached the default loopback driver instead of the VDA5050 driver, with no error reported anywhere. | D9: Technical | E9: Critical | F9: The VDA5050 integration could never work through the WES upload path. Two days were spent looking for the fault in the MQTT layer and the vehicle simulator before the loss was traced to the upload path. | G9: HungPV | H9: HungPV | J9: Added property to the parser's array tags and a properties field to the vehicle DTO. Verified end to end: uploading the VDA5050 map through WES now delivers all 9 properties to the kernel. 292 tests pass. | K9: Open | M9: Remains open because properties of point, path and location elements are still dropped by the same parser - same defect class, not yet fixed.
A10: I-006 | B10: 2026-07-17 | C10: Vehicles oscillated back and forth instead of making progress. The anti-starvation mechanism raised a vehicle's priority only while it appeared stuck, and stuck was measured against the distance travelled since the previous step. A vehicle moving back and forth therefore kept resetting its own counter and never earned the boost, while a vehicle standing completely still did - so oscillating was rewarded over waiting. | D10: Technical | E10: High | F10: Longer completion times across the fleet and repeated resource-claim churn, worsening as fleet size grew. | G10: HungPV | H10: HungPV | J10: Measured progress against the best distance achieved so far and against the current leg goal, rather than against the previous step. Measured result: 10 vehicles -15% ticks, 25 vehicles -40% ticks, claim churn -48% and -63%, solver failures 14 down to 8, suite 128 of 128 green. | K10: Closed | L10: 2026-07-20 | M10: The flips counter did not detect this fix (-2%) and must not be used as a health metric - it counts changes, not reversals.
A11: I-007 | B11: 2026-07-13 | C11: Vehicles stopped responding and had to be reset. When the resource claim held by the scheduler drifted out of step with the allocation actually being requested, the kernel rejected the request with an exception that killed the vehicle's command pump, leaving the vehicle alive but unable to accept any further movement. | D11: Technical | E11: Low | F11: Individual vehicles dropped out of service during a run until restarted. | G11: HungPV | H11: HungPV | J11: The scheduler now re-syncs the claim before allocating: it locates the requested allocation on the claimed route and drops the stale prefix, so the rejected condition no longer arises. No exception handler was added - the cause was removed. | K11: Closed | L11: 2026-07-13 | M11: Residual: when the requested allocation is not on the claimed route at all, the repair re-claims it alone and look-ahead is lost until the next drive order update. Logged as a warning and self-recovering, but it degrades routing quality - watch it as fleet size grows.
A12: I-008 | B12: 2026-07-28 | C12: During live batches vehicles were repeatedly ordered onto park points that another vehicle already occupied. The order neither completed nor failed - openTCS applies no timeout to a transport order and never reassigns one pinned to a vehicle - so the vehicle waited at the adjacent point until an operator withdrew the order by hand. | D12: Technical | E12: High | F12: Fleet throughput degraded and manual intervention was required on every occurrence. No data loss. | G12: HungPV | H12: HungPV | J12: Root-caused to the park-claim release rule (D-010) and to claims being lost on restart (D-011). Both fixed 2026-07-29; park orders fell from 214 to 4 per 80 deliveries. | K12: Closed | L12: 2026-07-29 | M12: Kernel behaviour confirmed by three controlled experiments against a live kernel, recorded in wes/report/park-claims-findings.md.
A13: I-009 | E13: Medium | K13: Open
A14: I-010 | E14: Medium | K14: Open
A15: I-011 | E15: Medium | K15: Open
A16: I-012 | E16: Medium | K16: Open
A17: I-013 | E17: Medium | K17: Open
A18: I-014 | E18: Medium | K18: Open
A19: I-015 | E19: Medium | K19: Open
A20: I-016 | E20: Medium | K20: Open
A21: I-017 | E21: Medium | K21: Open
A22: I-018 | E22: Medium | K22: Open
A23: I-019 | E23: Medium | K23: Open
A24: I-020 | E24: Medium | K24: Open

Sheet Risks
A1: Risks — Risk Register & Mitigation Tracking
A2: Probability: High(3) / Medium(2) / Low(1) · Impact: High(3) / Medium(2) / Low(1) · Risk Score = P × I · Score ≥ 6 = Critical; 4-5 = High; 2-3 = Medium; 1 = Low
A5: # | B5: Risk Description | C5: Category | D5: Probability | E5: Impact | F5: Risk Score (P×I) | G5: Mitigation Plan | H5: Contingency Plan | I5: Owner | J5: Due Date | K5: Status | L5: Notes
A6: R-001 | B6: MAPF solver stability degrades as the fleet grows — the measured breaking point lies between 10 and 20 vehicles, and behaviour above 25 vehicles is untested | C6: Technical | D6: Medium | E6: High | F6: 6 | G6: Certify at 10 vehicles where the solver is deterministic; re-run the fleet-scale sweep after every solver change; keep the LaCAM node budget bounded (200k) so runs stay reproducible | H6: Cap fleet size for the demo and record the ceiling as a known limitation in the final report | I6: HungPV | J6: Week 11 | K6: Open
A7: R-002 | B7: Key team member unavailable (illness, withdrawal) mid-project | C7: Resource | D7: Low | E7: High | F7: 3 | G7: Cross-train all members on critical modules; maintain shared knowledge base | H7: Reassign tasks; PM escalates to instructor if unresolvable | I7: PM | K7: Open
A8: R-003 | B8: Requirements change after SRS v1.0 is approved (scope creep) | C8: Scope | D8: Medium | E8: Medium | F8: 4 | G8: Strict change control: all changes go through ChangeLog; no mid-sprint changes | H8: Negotiate scope with the supervisor; defer low-priority features to a later iteration | I8: PM | K8: Open
A9: R-004 | B9: Stabilisation work (deadlock/ADG-acyclicity, commit horizon, claim resync, park-on-idle, VDA5050 wiring) is not described in any SRS or SDS section — engineering effort that cannot be credited at acceptance | C9: Technical | D9: High | E9: High | F9: 9 | G9: Write every added behaviour, config flag and failure mode back into the owning report section; fill SRS §4.1 External Interfaces (openTCS REST/SSE, VDA5050 MQTT), currently an empty table | H9: Publish a technical appendix in the Final Report covering the undocumented modules | I9: HungPV | J9: Week 8 | K9: Open
A10: R-005 | B10: Battery flow has no acceptance path — the discharge timer in the AGV simulator is still commented out, so the operational and charging battery thresholds (WBS #6, #7) cannot be exercised | C10: Technical | D10: Medium | E10: Medium | F10: 4 | G10: Re-enable the discharge timer in AgvSimulator before Iteration 1 closes | H10: Drive battery state directly over MQTT to exercise the thresholds manually | I10: HungPV | J10: Week 7 | K10: Closed | L10: Resolved 2026-07-23: the simulator now self-discharges (updateBattery) and forced charging was verified live (V01 charged from 71% to 100% at a CHARGE location). Mitigation completed.
A11: R-006 | B11: UAT findings require significant rework, delaying go-live | C11: Quality | D11: Medium | E11: High | F11: 6 | G11: Demo working features to the supervisor every two weeks; keep UAT acceptance criteria visible from Iteration 1 | H11: Prioritise P1 fixes; defer the rest and record them as known limitations | I11: PM | J11: Week 13 | K11: Open
A12: R-007 | B12: The MAPF planner feeds every localised vehicle into the solver as a mobile agent, including vehicles the fleet has been told to ignore (TO_BE_RESPECTED) and vehicles that have lost communication. This is harmless today because a vehicle standing on its goal is treated as a hard obstacle and push-aside is not implemented; enabling push-aside or relocation would let the solver plan moves for a vehicle that cannot move, hanging every plan queued behind it. | C12: Technical | D12: Low | E12: High | F12: 6 | G12: Keep push-aside and relocation switched off until readFleet filters the agent list by mobility; before either is enabled, exclude ignored, disconnected and manually controlled vehicles from the solver input and pass them in as static obstacles instead. | H12: Fall back to routing around the immobile vehicle in static-obstacle mode and raise it to the operator for manual clearing. | I12: HungPV | K12: Open | L12: Identified 2026-07-23 by code review; no incident observed. The exposure is dormant - it becomes live only when a push-aside or relocation feature is turned on.
A13: R-009 | B13: The lane-safety guard on cargo creation only inspects transport tasks in PICKING_UP. A vehicle crossing a pickup lane under a PARK or CHARGE order falls outside the rule, so cargo can still be declared at a slot on that vehicle's route and the vehicle may drive into it. openTCS does not model cargo as a scheduler resource, so nothing at the kernel level prevents this. | C13: Technical | D13: Medium | E13: High | F13: 6 | G13: Verify on map v7-vda5050.xml whether park and charge routes actually cross pickup lanes. If they do, extend the guard to withdraw the transiting order as well - WES issues those orders itself, so the same withdraw path applies. | H13: Operator clears the lane by hand and the transiting order is withdrawn manually from the dashboard. | I13: HungPV | K13: Open | L13: Identified 2026-07-28 while designing the lane-safety guard; accepted deliberately when the guard was narrowed from claimedResources to allocatedResources. claimedResources would have covered this case but blocks every lane along a planned route. Not observed in operation; the probability is unverified because the map has not been checked.
A14: R-010 | B14: LaneSafetyService treats an unresolvable vehicle state as safe: a vehicle missing from the state store yields an empty allocated-resource list, which reads as 'outside the lane' and lets cargo creation proceed. A PICKING_UP task whose metadata carries no assigned vehicle name is skipped by the check yet is still preempted. | C14: Technical | D14: Low | E14: High | F14: 3 | G14: Refuse cargo creation when the vehicle state behind a deeper PICKING_UP task cannot be resolved, instead of falling through to the safe branch. | H14: Operator re-checks the lane visually before placing the box. | I14: HungPV | K14: Open | L14: Identified 2026-07-28 by code review of lane-safety.service.ts, not by an incident. It contradicts the fail-closed principle applied elsewhere in the same guard, where an SSE disconnect falls back to a REST read rather than guessing.
A15: R-011 | B15: The charge engine keeps its charge-slot claims only in process memory and treats an unreachable kernel as proof that a charge order has ended - the same two faults that produced the park-point defects D-010 and D-011, still unfixed for charging. | C15: Technical | D15: Medium | E15: Medium | F15: 4 | G15: Apply the park-claim fixes to chargeTargets: rebuild the map from the kernel on bootstrap, and use getTransportOrderStateStrict so an unreachable kernel keeps the claim instead of dropping it. | H15: Operator withdraws the duplicate charge order; the vehicle re-evaluates on the next dispatch cycle. | I15: HungPV | K15: Open | L15: reconcileChargeTargets already compares the exact order name, which is why charging never developed the churn parking did. Only the restart and the fail-open branch remain.
A16: R-012 | D16: Medium | E16: Medium | K16: Open
A17: R-013 | D17: Medium | E17: Medium | K17: Open
A18: R-014 | D18: Medium | E18: Medium | K18: Open
A19: R-015 | D19: Medium | E19: Medium | K19: Open

Sheet ChangeLog
A1: ChangeLog — Requirement & Scope Change Tracking
A2: Log ALL changes to requirements, design, or scope · No mid-sprint changes without approval · Reference this log when versions of SRS/SDS increment
A4: # | B4: Date | C4: Change Description | D4: Requested By | E4: Affects (SRS/WBS/Code) | F4: Impact on Scope | G4: Impact on Effort (pds) | H4: Impact on Timeline | I4: Priority | J4: Approved By | K4: Status | L4: Notes
A5: C-001 | B5: 2026-07-20 | C5: FE-01: replace UC 12/13 with Activate/Deactivate AGV and mid-task disconnection handling | D5: HungPV | E5: SRS 1.3.2, 2.1; WBS #12-13 | F5: Net 0 UC (-2/+2); adds 1 Non-UI function | G5: +7 pts (6 to 13) | H5: None; both in Iteration 2 | I5: Medium | K5: Pending | L5: Search over 20 vehicles did not need its own UC
A6: C-002 | B6: 2026-07-20 | C6: Correct BR-01 and MSG-15: charging threshold must be LOWER than operational, not greater | D6: HungPV | E6: SRS 5.1 BR-01; 5.2 MSG-15 | F6: None | G6: 0 | H6: None | I6: Medium | K6: Pending | L6: Stated rule contradicted defaults 20 / 10
A7: C-003 | B7: 2026-07-20 | C7: FE-01 spec aligned to build: AGV keyed by code not MAC; no status column; AGV APIs Admin-only | D7: HungPV | E7: SRS 1.3.2, 1.4.2, 2.1, 5.1, 5.2 | F7: Operator loses AGV read access; BR-03 deferred | G7: 0 | H7: None | I7: Medium | K7: Pending | L7: BR-06: ignored AGV still a routing obstacle
A8: C-004 | B8: 2026-07-20 | C8: FE-02: drop map topology editing; add UC 37/38/39; UC 32 narrowed to name and colour | D8: HungPV | E8: SRS 1.3.2, 2.2, 1.5, 5.1, 5.2 | F8: Point/path/block management removed; 3 implemented UCs documented | G8: 0 | H8: None | I8: Medium | K8: Pending | L8: Topology is edited in the openTCS Model Editor, not in WES
A9: C-005 | B9: 2026-07-22 | C9: Charging (BR-03) promoted to this release; 2-threshold battery model (critical 20% / sufficient 60%). | D9: HungPV | I9: Medium | K9: Pending
A10: C-006 | B10: 2026-07-22 | C10: WBS: added the 18 non-UI functions from SRS §1.4.3 as tracked tasks. | D10: HungPV | I10: Medium | K10: Pending
A11: C-007 | B11: 2026-07-28 | C11: Lane-safety guard on cargo creation. Cargo may not be declared at a slot shallower than a cargo already being picked in the same lane while the assigned vehicle holds allocated resources inside that lane; when the vehicle is still outside, creation proceeds and its pickup order is withdrawn synchronously in the same request. Preempt responsibility moved out of ReleaseEngineService into the cargo creation path. | D11: HungPV | E11: SRS 5.1 (new BR-16), UC Create Cargo, SRS 4.1 External Interfaces; SDS 3 (LaneSafetyService, ReleaseEngineService); code | F11: No new use case. One new business rule and one refused-creation path added to an existing use case. | G11: 0 | H11: None | I11: Medium | K11: Pending | L11: allocatedResources chosen over claimedResources: allocated covers the commands already sent to the vehicle, which withdraw(immediate=false) cannot cancel. Ordering, not the database transaction, provides the safety property - a transaction cannot roll back an HTTP withdrawal. Known gaps logged as R-009 and R-010.
A12: C-008 | B12: 2026-07-29 | C12: Idle parking is suppressed while any transport task is CREATED, READY_TO_ASSIGN or BLOCKED, not only READY_TO_ASSIGN as before. | D12: HungPV | E12: SDS 3.1.10; Code | F12: None | G12: 0 | H12: None | I12: Medium | K12: Pending | L12: A task is written CREATED and only classified on the next flush by the release engine, so the previous gate sent a vehicle away to park one flush before the assignment engine asked for it.
A13: C-009 | B13: 2026-07-29 | C13: Park-order disposal delegated to openTCS: park orders now carry dispensable=true and WES no longer withdraws them. The assignment-engine park preempt and the PARK_IDLE_DELAY_MS knob are removed. | D13: HungPV | E13: SDS 2.4, 3.1.10 and config table; Code | F13: None | G13: 0 | H13: None | I13: Medium | K13: Pending | L13: SDS 3.1.10 still documents PARK_IDLE_DELAY_MS (as 10000ms), the idleSince and parkTargets attributes and the park preempt in assign() - all removed. SDS 3.1.10 also lists only four flush engines; there are now six steps.
A14: C-010 | B14: 2026-07-30 | C14: WBS status correction. Eleven rows recorded as Not Started or In Progress are in fact delivered and verified in code: the operation dashboard and six of its KPI cards (WBS 56, 59, 60, 62, 63, 64, 65), the Charge Engine (WBS 94), and the assigned-vehicle and execution-progress views (WBS 35, 36), which are delivered on the live operation map rather than in the Cargo table. WBS 7 moves from Not Started to In Progress: the sufficient-battery threshold exists in the API and the Charge Engine already uses it; only the input field is missing. | D14: HungPV | E14: WBS | F14: None - no requirement added or removed | G14: 0 | H14: None | I14: Medium | K14: Pending
A15: C-011 | B15: 2026-07-30 | C15: WBS: added feature group FE-08 Multi-Agent Traffic Coordination (FMS layer) with four Non-UI rows - the LaCAM* multi-agent router that replaces the stock per-vehicle Dijkstra router, the ADG per-visit precedence and acyclicity gate, the rolling-horizon commit that accepts a plan only when the solver proves it executable, and the PIBT engine with its anti-starvation priority. | D15: HungPV | E15: Report 1 FE-08 (GAP-04); SDS 4; WBS | F15: No new requirement. FE-08 was already a committed feature in Report 1 v1.1.0 (16/07/2026) but had no work breakdown at all. | G15: +32 pts (500 to 532) | H15: None - the work is already complete | I15: Medium | K15: Pending
A16: C-012 | B16: 2026-08-02 | C16: WBS: added row #118 Parking Engine (idle parking) as a Non-UI function under FE-01, sub-feature Idle Management, Complex / 8 pts / Iteration 3 / Done. The engine is delivered and verified in code (parking-engine.service.ts, park-claim.store.ts) but had no work-breakdown row - it appeared in this file only as defects D-010 and D-011 and issue I-008. | D16: HungPV | E16: SRS 1.4.3 (Non-UI function #21); SDS 3.1.10; WBS | F16: No new requirement - the function is already specified in SRS 1.4.3 and the work is complete. | G16: +8 pts (532 to 540) | H16: None - the work is already complete | I16: Medium | K16: Pending | L16: Iteration 3: 24 -> 25 chức năng, 116 -> 124 pts, Done 7 -> 8; Grand Total 114 -> 115 và 532 -> 540 pts. Kèm theo C-009: SDS 3.1.10 vẫn mô tả PARK_IDLE_DELAY_MS và park preempt đã bị gỡ, cần sửa riêng.
A17: C-013 | B17: 2026-08-02 | C17: Feature group FE-04 renamed from "Traffic Routing & Dispatch" to "Dispatch Orchestration & Release Control" to match Report 1 v1.1.0 (Table I-8), which already states that route planning and traffic coordination belong to the FMS layer (FE-08). WBS #51 View traffic congestion alerts is cancelled and merged into #66; #52 View deadlock risk alerts and #53 View projected AGV route move to FE-05. Sub-feature Route Analysis is replaced by Assignment Explainability (#54) and Assignment Logic (#103). | D17: HungPV | E17: Report 1 Table I-8 (source of truth); SRS 1.3.2 (group TRD -> DOR), 1.3.2.5, 1.4.3 rows 8-9; WBS | F17: No requirement added or removed - one screen merged into an existing one (UC 67 into UC 82). | G17: 0 - the merged screen keeps the estimate of #66 | H17: None | I17: Medium | K17: Pending | L17: WBS và SRS mang tên cũ trước Report 1 v1.1.0 (16/07/2026). FE-04 sau khi dọn chỉ còn: Policy Configuration, Queue Management, Assignment Explainability, Resource Allocation và hai engine Non-UI. Tổng số dòng và pts không đổi (#51 chuyển sang Cancelled, vốn đang Not Started).
A18: C-014 | B18: 2026-08-02 | C18: WBS #47 renamed from "Update AGV dispatch policy" - an exact duplicate of #46 - to "View transport request dispatch queue", matching UC 63 in SRS 1.3.2 and the description already carried on the same row ("View the list of requests waiting to be orchestrated"). Copy-paste data-entry error: the row was always the dispatch-queue screen (sub-feature Queue Management, Medium / 5 pts / Iteration 2); only the task name was wrong. Not a scope change. | D18: HungPV | E18: WBS; SRS 1.3.2 (UC 63) | F18: None - data-entry correction, no requirement added or removed. | G18: 0 | H18: None | I18: Medium | K18: Pending
A19: C-015 | B19: 2026-08-04 | C19: Dispatch documentation realigned with the implemented engine. SRS Non-UI Functions #7, #8 and #9 rewritten (withdrawal also covers lane-safety preemption; the release engine is a stage of an event-driven flush with a 5-second fleet-state heartbeat, not a periodic scan; task selection is FIFO because weight_urgency, weight_proximity and weight_inventory_position were dropped from the schema, leaving weight_battery). Added #26 Lane Safety Guard & Pickup Preemption and #27 Dispatch Counterfactual Recorder - both live but undocumented - and the matching WBS rows #119 and #120. UC 71 moved to Warehouse Map & Topology in both SRS and WBS; UC 63/64 recorded as delivered through the Cargo view. | D19: HungPV | E19: SRS II.1.4.3, II.1.3.2, II.1.4.2, II.1.5, II.4.2.2, II.5.2; WBS #55, #119, #120 | F19: No requirement added or removed. Two already-delivered Non-UI functions are now documented (+13 pts recognised, not new work); one use case reassigned to another feature group. | G19: 13 | H19: None | I19: Medium | K19: Pending | L19: Phát hiện khi rà code-vs-docs ngày 04/08: ba trọng số dispatch đã bị drop khỏi schema bởi migration 1796/1797 nhưng docs vẫn mô tả, và hai chức năng đang chạy production thì không có dòng nào trong báo cáo.
